# tests/test_force_fail.py
def test_force_fail():
    assert False, "Intentional failure for anomaly data"
